Workbook
Name Apartada: 'Cadastro de Sócios'!$K$2
Name Ativo: 'Plano de Contas'!$A$2:$A$5
Name Crédito: 'Plano de Contas'!$G$2:$G$14
Name Débito: 'Plano de Contas'!$F$2:$F$14
Name Despesas: 'Plano de Contas'!$A$14:$A$16
Name Espécie: 'Cadastro de Sócios'!$J$2:$J$3
Name Estrutura: 'Cadastro de Sócios'!$A$9
Name Geral: 'Cadastro de Sócios'!$K$2:$K$8
Name Mês: Despesas!$A$3:$A$14
Name Natureza: 'Plano de Contas'!$I$2:$I$5
Name Passivo: 'Plano de Contas'!$A$6:$A$8
Name PL: 'Plano de Contas'!$A$9:$A$11
Name Receita: 'Plano de Contas'!$A$13
Name Responsável: 'Cadastro de Sócios'!$A$2:$A$8
Name Situação: 'Cadastro de Sócios'!$I$2:$I$6

Sheet Entradas
A1: Cliente | B1: Data | C1: Valor Recebido (R$) | D1: André Savio | E1: Bruna Leão | F1: Fernanda Canha | G1: Nicole Pazzini | H1: Bianka Lima | I1: Daniele | J1: Luciane
A2: Rodrigo Velho de Almeida | B2: 45825 | C2: 1500 | D2: 0.5 | E2: 0.5 | F2: 0 | G2: 0 | H2: 0 | I2: 0 | J2: 0 | K2: 0 | L2: 0
A3: Taiana | B3: 45869 | C3: 330 | D3: 1 | E3: 0 | F3: 0 | G3: 0 | H3: 0 | I3: 0 | J3: 0 | K3: 0 | L3: 0
A4: Taiana | B4: 45898 | C4: 330 | D4: 1 | E4: 0 | F4: 0 | G4: 0 | H4: 0 | I4: 0 | J4: 0 | K4: 0 | L4: 0
A5: NOVO BRECHO E OUTLET | B5: 45966 | C5: 100 | D5: 0.5 | E5: 0.5 | F5: 0 | G5: 0 | H5: 0 | I5: 0 | J5: 0 | K5: 0 | L5: 0
A6: F F DE FREITAS LTDA | B6: 45971 | C6: 350 | D6: 0.25 | E6: 0.75 | F6: 0 | G6: 0 | H6: 0 | I6: 0 | J6: 0 | K6: 0 | L6: 0
A7: F F DE FREITAS LTDA | B7: 45971 | C7: 600 | D7: 0.1 | E7: 0.9 | F7: 0 | G7: 0 | H7: 0 | I7: 0 | J7: 0 | K7: 0 | L7: 0
A8: F F DE FREITAS LTDA | B8: 45971 | C8: 450 | D8: 0.1 | E8: 0.9 | F8: 0 | G8: 0 | H8: 0 | I8: 0 | J8: 0 | K8: 0 | L8: 0
A9: F F DE FREITAS LTDA | B9: 45971 | C9: 100 | D9: 0.5 | E9: 0.5 | F9: 0 | G9: 0 | H9: 0 | I9: 0 | J9: 0 | K9: 0 | L9: 0
B10: 45658 | C10: 0 | D10: 0 | E10: 0 | F10: 0 | G10: 0 | H10: 0 | I10: 0 | J10: 0 | K10: 0 | L10: 0
B11: 45658 | C11: 0 | D11: 0 | E11: 0 | F11: 0 | G11: 0 | H11: 0 | I11: 0 | J11: 0 | K11: 0 | L11: 0
B12: 45658 | C12: 0 | D12: 0 | E12: 0 | F12: 0 | G12: 0 | H12: 0 | I12: 0 | J12: 0 | K12: 0 | L12: 0
B13: 45658 | C13: 0 | D13: 0 | E13: 0 | F13: 0 | G13: 0 | H13: 0 | I13: 0 | J13: 0 | K13: 0 | L13: 0
B14: 45658 | C14: 0 | D14: 0 | E14: 0 | F14: 0 | G14: 0 | H14: 0 | I14: 0 | J14: 0 | K14: 0 | L14: 0

Sheet Despesas
A1: Demonstrativo de Custos Gerais por Mês | D1: Lista de Despesas Gerais | K1: Lista de Despesa Individual
A2: Mês | B2: Despesas Gerais | D2: Data | E2: Espécie | F2: Responsável | G2: Tipo | H2: Descrição | I2: Valor | K2: Data | L2: André Savio | M2: Bruna Leão | N2: Fernanda Canha | O2: Nicole Pazzini | P2: Bianka Lima | Q2: Daniele | R2: Luciane
A3: 45658 | B3: =SUMIFS(I:I, D:D, DATE(2025,1,1), E:E, "Estrutura") -> 0 | D3: 45658 | E3: Estrutura | F3: L&S | G3: Estagiário | I3: 0 | K3: 45658 | L3: {=SUMPRODUCT( (MONTH($D$3:$D$101) = MONTH($K3)) * (YEAR($D$3:$D$101) = YEAR($K3)) * ($E$3:$E$101 = "Individual/Setor") * ($F$3:$F$101 = L$2) * ($I$3:$I$101) )} -> 0 | M3: {=SUMPRODUCT( (MONTH($D$3:$D$101) = MONTH($K3)) * (YEAR($D$3:$D$101) = YEAR($K3)) * ($E$3:$E$101 = "Individual/Setor") * ($F$3:$F$101 = M$2) * ($I$3:$I$101) )} -> 0 | N3: {=SUMPRODUCT( (MONTH($D$3:$D$101) = MONTH($K3)) * (YEAR($D$3:$D$101) = YEAR($K3)) * ($E$3:$E$101 = "Individual/Setor") * ($F$3:$F$101 = N$2) * ($I$3:$I$101) )} -> 0 | O3: {=SUMPRODUCT( (MONTH($D$3:$D$101) = MONTH($K3)) * (YEAR($D$3:$D$101) = YEAR($K3)) * ($E$3:$E$101 = "Individual/Setor") * ($F$3:$F$101 = O$2) * ($I$3:$I$101) )} -> 0 | P3: {=SUMPRODUCT( (MONTH($D$3:$D$101) = MONTH($K3)) * (YEAR($D$3:$D$101) = YEAR($K3)) * ($E$3:$E$101 = "Individual/Setor") * ($F$3:$F$101 = P$2) * ($I$3:$I$101) )} -> 0 | Q3: {=SUMPRODUCT( (MONTH($D$3:$D$101) = MONTH($K3)) * (YEAR($D$3:$D$101) = YEAR($K3)) * ($E$3:$E$101 = "Individual/Setor") * ($F$3:$F$101 = Q$2) * ($I$3:$I$101) )} -> 0 | R3: {=SUMPRODUCT( (MONTH($D$3:$D$101) = MONTH($K3)) * (YEAR($D$3:$D$101) = YEAR($K3)) * ($E$3:$E$101 = "Individual/Setor") * ($F$3:$F$101 = R$2) * ($I$3:$I$101) )} -> 0 | S3: {=SUMPRODUCT( (MONTH($D$3:$D$101) = MONTH($K3)) * (YEAR($D$3:$D$101) = YEAR($K3)) * ($E$3:$E$101 = "Individual/Setor") * ($F$3:$F$101 = S$2) * ($I$3:$I$101) )} -> 0 | T3: {=SUMPRODUCT( (MONTH($D$3:$D$101) = MONTH($K3)) * (YEAR($D$3:$D$101) = YEAR($K3)) * ($E$3:$E$101 = "Individual/Setor") * ($F$3:$F$101 = T$2) * ($I$3:$I$101) )} -> 0
A4: 45689 | B4: =SUMIFS(I:I, D:D, DATE(2025,2,1), E:E, "Estrutura") -> 0 | D4: 45658 | E4: Estrutura | F4: L&S | G4: Condomínio | I4: 0 | K4: 45689 | L4: {=SUMPRODUCT( (MONTH($D$3:$D$101) = MONTH($K4)) * (YEAR($D$3:$D$101) = YEAR($K4)) * ($E$3:$E$101 = "Individual/Setor") * ($F$3:$F$101 = L$2) * ($I$3:$I$101) )} -> 0 | M4: {=SUMPRODUCT( (MONTH($D$3:$D$101) = MONTH($K4)) * (YEAR($D$3:$D$101) = YEAR($K4)) * ($E$3:$E$101 = "Individual/Setor") * ($F$3:$F$101 = M$2) * ($I$3:$I$101) )} -> 0 | N4: {=SUMPRODUCT( (MONTH($D$3:$D$101) = MONTH($K4)) * (YEAR($D$3:$D$101) = YEAR($K4)) * ($E$3:$E$101 = "Individual/Setor") * ($F$3:$F$101 = N$2) * ($I$3:$I$101) )} -> 0 | O4: {=SUMPRODUCT( (MONTH($D$3:$D$101) = MONTH($K4)) * (YEAR($D$3:$D$101) = YEAR($K4)) * ($E$3:$E$101 = "Individual/Setor") * ($F$3:$F$101 = O$2) * ($I$3:$I$101) )} -> 0 | P4: {=SUMPRODUCT( (MONTH($D$3:$D$101) = MONTH($K4)) * (YEAR($D$3:$D$101) = YEAR($K4)) * ($E$3:$E$101 = "Individual/Setor") * ($F$3:$F$101 = P$2) * ($I$3:$I$101) )} -> 0 | Q4: {=SUMPRODUCT( (MONTH($D$3:$D$101) = MONTH($K4)) * (YEAR($D$3:$D$101) = YEAR($K4)) * ($E$3:$E$101 = "Individual/Setor") * ($F$3:$F$101 = Q$2) * ($I$3:$I$101) )} -> 0 | R4: {=SUMPRODUCT( (MONTH($D$3:$D$101) = MONTH($K4)) * (YEAR($D$3:$D$101) = YEAR($K4)) * ($E$3:$E$101 = "Individual/Setor") * ($F$3:$F$101 = R$2) * ($I$3:$I$101) )} -> 0 | S4: {=SUMPRODUCT( (MONTH($D$3:$D$101) = MONTH($K4)) * (YEAR($D$3:$D$101) = YEAR($K4)) * ($E$3:$E$101 = "Individual/Setor") * ($F$3:$F$101 = S$2) * ($I$3:$I$101) )} -> 0 | T4: {=SUMPRODUCT( (MONTH($D$3:$D$101) = MONTH($K4)) * (YEAR($D$3:$D$101) = YEAR($K4)) * ($E$3:$E$101 = "Individual/Setor") * ($F$3:$F$101 = T$2) * ($I$3:$I$101) )} -> 0
A5: 45717 | B5: =SUMIFS(I:I, D:D, DATE(2025,3,1), E:E, "Estrutura") -> 0 | D5: 45658 | E5: Individual/Setor | F5: Bruna Leão | G5: Estagiário | I5: 0 | K5: 45717 | L5: {=SUMPRODUCT( (MONTH($D$3:$D$101) = MONTH($K5)) * (YEAR($D$3:$D$101) = YEAR($K5)) * ($E$3:$E$101 = "Individual/Setor") * ($F$3:$F$101 = L$2) * ($I$3:$I$101) )} -> 0 | M5: {=SUMPRODUCT( (MONTH($D$3:$D$101) = MONTH($K5)) * (YEAR($D$3:$D$101) = YEAR($K5)) * ($E$3:$E$101 = "Individual/Setor") * ($F$3:$F$101 = M$2) * ($I$3:$I$101) )} -> 0 | N5: {=SUMPRODUCT( (MONTH($D$3:$D$101) = MONTH($K5)) * (YEAR($D$3:$D$101) = YEAR($K5)) * ($E$3:$E$101 = "Individual/Setor") * ($F$3:$F$101 = N$2) * ($I$3:$I$101) )} -> 0 | O5: {=SUMPRODUCT( (MONTH($D$3:$D$101) = MONTH($K5)) * (YEAR($D$3:$D$101) = YEAR($K5)) * ($E$3:$E$101 = "Individual/Setor") * ($F$3:$F$101 = O$2) * ($I$3:$I$101) )} -> 0 | P5: {=SUMPRODUCT( (MONTH($D$3:$D$101) = MONTH($K5)) * (YEAR($D$3:$D$101) = YEAR($K5)) * ($E$3:$E$101 = "Individual/Setor") * ($F$3:$F$101 = P$2) * ($I$3:$I$101) )} -> 0 | Q5: {=SUMPRODUCT( (MONTH($D$3:$D$101) = MONTH($K5)) * (YEAR($D$3:$D$101) = YEAR($K5)) * ($E$3:$E$101 = "Individual/Setor") * ($F$3:$F$101 = Q$2) * ($I$3:$I$101) )} -> 0 | R5: {=SUMPRODUCT( (MONTH($D$3:$D$101) = MONTH($K5)) * (YEAR($D$3:$D$101) = YEAR($K5)) * ($E$3:$E$101 = "Individual/Setor") * ($F$3:$F$101 = R$2) * ($I$3:$I$101) )} -> 0 | S5: {=SUMPRODUCT( (MONTH($D$3:$D$101) = MONTH($K5)) * (YEAR($D$3:$D$101) = YEAR($K5)) * ($E$3:$E$101 = "Individual/Setor") * ($F$3:$F$101 = S$2) * ($I$3:$I$101) )} -> 0 | T5: {=SUMPRODUCT( (MONTH($D$3:$D$101) = MONTH($K5)) * (YEAR($D$3:$D$101) = YEAR($K5)) * ($E$3:$E$101 = "Individual/Setor") * ($F$3:$F$101 = T$2) * ($I$3:$I$101) )} -> 0
A6: 45748 | B6: =SUMIFS(I:I, D:D, DATE(2025,4,1), E:E, "Estrutura") -> 0 | D6: 45658 | E6: Estrutura | F6: L&S | G6: Internet | I6: 0 | K6: 45748 | L6: {=SUMPRODUCT( (MONTH($D$3:$D$101) = MONTH($K6)) * (YEAR($D$3:$D$101) = YEAR($K6)) * ($E$3:$E$101 = "Individual/Setor") * ($F$3:$F$101 = L$2) * ($I$3:$I$101) )} -> 0 | M6: {=SUMPRODUCT( (MONTH($D$3:$D$101) = MONTH($K6)) * (YEAR($D$3:$D$101) = YEAR($K6)) * ($E$3:$E$101 = "Individual/Setor") * ($F$3:$F$101 = M$2) * ($I$3:$I$101) )} -> 0 | N6: {=SUMPRODUCT( (MONTH($D$3:$D$101) = MONTH($K6)) * (YEAR($D$3:$D$101) = YEAR($K6)) * ($E$3:$E$101 = "Individual/Setor") * ($F$3:$F$101 = N$2) * ($I$3:$I$101) )} -> 0 | O6: {=SUMPRODUCT( (MONTH($D$3:$D$101) = MONTH($K6)) * (YEAR($D$3:$D$101) = YEAR($K6)) * ($E$3:$E$101 = "Individual/Setor") * ($F$3:$F$101 = O$2) * ($I$3:$I$101) )} -> 0 | P6: {=SUMPRODUCT( (MONTH($D$3:$D$101) = MONTH($K6)) * (YEAR($D$3:$D$101) = YEAR($K6)) * ($E$3:$E$101 = "Individual/Setor") * ($F$3:$F$101 = P$2) * ($I$3:$I$101) )} -> 0 | Q6: {=SUMPRODUCT( (MONTH($D$3:$D$101) = MONTH($K6)) * (YEAR($D$3:$D$101) = YEAR($K6)) * ($E$3:$E$101 = "Individual/Setor") * ($F$3:$F$101 = Q$2) * ($I$3:$I$101) )} -> 0 | R6: {=SUMPRODUCT( (MONTH($D$3:$D$101) = MONTH($K6)) * (YEAR($D$3:$D$101) = YEAR($K6)) * ($E$3:$E$101 = "Individual/Setor") * ($F$3:$F$101 = R$2) * ($I$3:$I$101) )} -> 0 | S6: {=SUMPRODUCT( (MONTH($D$3:$D$101) = MONTH($K6)) * (YEAR($D$3:$D$101) = YEAR($K6)) * ($E$3:$E$101 = "Individual/Setor") * ($F$3:$F$101 = S$2) * ($I$3:$I$101) )} -> 0 | T6: {=SUMPRODUCT( (MONTH($D$3:$D$101) = MONTH($K6)) * (YEAR($D$3:$D$101) = YEAR($K6)) * ($E$3:$E$101 = "Individual/Setor") * ($F$3:$F$101 = T$2) * ($I$3:$I$101) )} -> 0
A7: 45778 | B7: =SUMIFS(I:I, D:D, DATE(2025,5,1), E:E, "Estrutura") -> 0 | D7: 45658 | E7: Estrutura | F7: L&S | G7: Condomínio | I7: 0 | K7: 45778 | L7: {=SUMPRODUCT( (MONTH($D$3:$D$101) = MONTH($K7)) * (YEAR($D$3:$D$101) = YEAR($K7)) * ($E$3:$E$101 = "Individual/Setor") * ($F$3:$F$101 = L$2) * ($I$3:$I$101) )} -> 0 | M7: {=SUMPRODUCT( (MONTH($D$3:$D$101) = MONTH($K7)) * (YEAR($D$3:$D$101) = YEAR($K7)) * ($E$3:$E$101 = "Individual/Setor") * ($F$3:$F$101 = M$2) * ($I$3:$I$101) )} -> 0 | N7: {=SUMPRODUCT( (MONTH($D$3:$D$101) = MONTH($K7)) * (YEAR($D$3:$D$101) = YEAR($K7)) * ($E$3:$E$101 = "Individual/Setor") * ($F$3:$F$101 = N$2) * ($I$3:$I$101) )} -> 0 | O7: {=SUMPRODUCT( (MONTH($D$3:$D$101) = MONTH($K7)) * (YEAR($D$3:$D$101) = YEAR($K7)) * ($E$3:$E$101 = "Individual/Setor") * ($F$3:$F$101 = O$2) * ($I$3:$I$101) )} -> 0 | P7: {=SUMPRODUCT( (MONTH($D$3:$D$101) = MONTH($K7)) * (YEAR($D$3:$D$101) = YEAR($K7)) * ($E$3:$E$101 = "Individual/Setor") * ($F$3:$F$101 = P$2) * ($I$3:$I$101) )} -> 0 | Q7: {=SUMPRODUCT( (MONTH($D$3:$D$101) = MONTH($K7)) * (YEAR($D$3:$D$101) = YEAR($K7)) * ($E$3:$E$101 = "Individual/Setor") * ($F$3:$F$101 = Q$2) * ($I$3:$I$101) )} -> 0 | R7: {=SUMPRODUCT( (MONTH($D$3:$D$101) = MONTH($K7)) * (YEAR($D$3:$D$101) = YEAR($K7)) * ($E$3:$E$101 = "Individual/Setor") * ($F$3:$F$101 = R$2) * ($I$3:$I$101) )} -> 0 | S7: {=SUMPRODUCT( (MONTH($D$3:$D$101) = MONTH($K7)) * (YEAR($D$3:$D$101) = YEAR($K7)) * ($E$3:$E$101 = "Individual/Setor") * ($F$3:$F$101 = S$2) * ($I$3:$I$101) )} -> 0 | T7: {=SUMPRODUCT( (MONTH($D$3:$D$101) = MONTH($K7)) * (YEAR($D$3:$D$101) = YEAR($K7)) * ($E$3:$E$101 = "Individual/Setor") * ($F$3:$F$101 = T$2) * ($I$3:$I$101) )} -> 0
A8: 45809 | B8: =SUMIFS(I:I, D:D, DATE(2025,6,1), E:E, "Estrutura") -> 0 | D8: 45658 | E8: Individual/Setor | F8: L&S | G8: Internet | I8: 0 | K8: 45809 | L8: {=SUMPRODUCT( (MONTH($D$3:$D$101) = MONTH($K8)) * (YEAR($D$3:$D$101) = YEAR($K8)) * ($E$3:$E$101 = "Individual/Setor") * ($F$3:$F$101 = L$2) * ($I$3:$I$101) )} -> 0 | M8: {=SUMPRODUCT( (MONTH($D$3:$D$101) = MONTH($K8)) * (YEAR($D$3:$D$101) = YEAR($K8)) * ($E$3:$E$101 = "Individual/Setor") * ($F$3:$F$101 = M$2) * ($I$3:$I$101) )} -> 0 | N8: {=SUMPRODUCT( (MONTH($D$3:$D$101) = MONTH($K8)) * (YEAR($D$3:$D$101) = YEAR($K8)) * ($E$3:$E$101 = "Individual/Setor") * ($F$3:$F$101 = N$2) * ($I$3:$I$101) )} -> 0 | O8: {=SUMPRODUCT( (MONTH($D$3:$D$101) = MONTH($K8)) * (YEAR($D$3:$D$101) = YEAR($K8)) * ($E$3:$E$101 = "Individual/Setor") * ($F$3:$F$101 = O$2) * ($I$3:$I$101) )} -> 0 | P8: {=SUMPRODUCT( (MONTH($D$3:$D$101) = MONTH($K8)) * (YEAR($D$3:$D$101) = YEAR($K8)) * ($E$3:$E$101 = "Individual/Setor") * ($F$3:$F$101 = P$2) * ($I$3:$I$101) )} -> 0 | Q8: {=SUMPRODUCT( (MONTH($D$3:$D$101) = MONTH($K8)) * (YEAR($D$3:$D$101) = YEAR($K8)) * ($E$3:$E$101 = "Individual/Setor") * ($F$3:$F$101 = Q$2) * ($I$3:$I$101) )} -> 0 | R8: {=SUMPRODUCT( (MONTH($D$3:$D$101) = MONTH($K8)) * (YEAR($D$3:$D$101) = YEAR($K8)) * ($E$3:$E$101 = "Individual/Setor") * ($F$3:$F$101 = R$2) * ($I$3:$I$101) )} -> 0 | S8: {=SUMPRODUCT( (MONTH($D$3:$D$101) = MONTH($K8)) * (YEAR($D$3:$D$101) = YEAR($K8)) * ($E$3:$E$101 = "Individual/Setor") * ($F$3:$F$101 = S$2) * ($I$3:$I$101) )} -> 0 | T8: {=SUMPRODUCT( (MONTH($D$3:$D$101) = MONTH($K8)) * (YEAR($D$3:$D$101) = YEAR($K8)) * ($E$3:$E$101 = "Individual/Setor") * ($F$3:$F$101 = T$2) * ($I$3:$I$101) )} -> 0
A9: 45839 | B9: =SUMIFS(I:I, D:D, DATE(2025,7,1), E:E, "Estrutura") -> 0 | D9: 45689 | E9: Estrutura | F9: L&S | G9: Internet | I9: 0 | K9: 45839 | L9: {=SUMPRODUCT( (MONTH($D$3:$D$101) = MONTH($K9)) * (YEAR($D$3:$D$101) = YEAR($K9)) * ($E$3:$E$101 = "Individual/Setor") * ($F$3:$F$101 = L$2) * ($I$3:$I$101) )} -> 0 | M9: {=SUMPRODUCT( (MONTH($D$3:$D$101) = MONTH($K9)) * (YEAR($D$3:$D$101) = YEAR($K9)) * ($E$3:$E$101 = "Individual/Setor") * ($F$3:$F$101 = M$2) * ($I$3:$I$101) )} -> 0 | N9: {=SUMPRODUCT( (MONTH($D$3:$D$101) = MONTH($K9)) * (YEAR($D$3:$D$101) = YEAR($K9)) * ($E$3:$E$101 = "Individual/Setor") * ($F$3:$F$101 = N$2) * ($I$3:$I$101) )} -> 0 | O9: {=SUMPRODUCT( (MONTH($D$3:$D$101) = MONTH($K9)) * (YEAR($D$3:$D$101) = YEAR($K9)) * ($E$3:$E$101 = "Individual/Setor") * ($F$3:$F$101 = O$2) * ($I$3:$I$101) )} -> 0 | P9: {=SUMPRODUCT( (MONTH($D$3:$D$101) = MONTH($K9)) * (YEAR($D$3:$D$101) = YEAR($K9)) * ($E$3:$E$101 = "Individual/Setor") * ($F$3:$F$101 = P$2) * ($I$3:$I$101) )} -> 0 | Q9: {=SUMPRODUCT( (MONTH($D$3:$D$101) = MONTH($K9)) * (YEAR($D$3:$D$101) = YEAR($K9)) * ($E$3:$E$101 = "Individual/Setor") * ($F$3:$F$101 = Q$2) * ($I$3:$I$101) )} -> 0 | R9: {=SUMPRODUCT( (MONTH($D$3:$D$101) = MONTH($K9)) * (YEAR($D$3:$D$101) = YEAR($K9)) * ($E$3:$E$101 = "Individual/Setor") * ($F$3:$F$101 = R$2) * ($I$3:$I$101) )} -> 0 | S9: {=SUMPRODUCT( (MONTH($D$3:$D$101) = MONTH($K9)) * (YEAR($D$3:$D$101) = YEAR($K9)) * ($E$3:$E$101 = "Individual/Setor") * ($F$3:$F$101 = S$2) * ($I$3:$I$101) )} -> 0 | T9: {=SUMPRODUCT( (MONTH($D$3:$D$101) = MONTH($K9)) * (YEAR($D$3:$D$101) = YEAR($K9)) * ($E$3:$E$101 = "Individual/Setor") * ($F$3:$F$101 = T$2) * ($I$3:$I$101) )} -> 0
A10: 45870 | B10: =SUMIFS(I:I, D:D, DATE(2025,8,1), E:E, "Estrutura") -> 0 | D10: 45689 | E10: Estrutura | F10: L&S | G10: Sistema de gestão | I10: 0 | K10: 45870 | L10: {=SUMPRODUCT( (MONTH($D$3:$D$101) = MONTH($K10)) * (YEAR($D$3:$D$101) = YEAR($K10)) * ($E$3:$E$101 = "Individual/Setor") * ($F$3:$F$101 = L$2) * ($I$3:$I$101) )} -> 0 | M10: {=SUMPRODUCT( (MONTH($D$3:$D$101) = MONTH($K10)) * (YEAR($D$3:$D$101) = YEAR($K10)) * ($E$3:$E$101 = "Individual/Setor") * ($F$3:$F$101 = M$2) * ($I$3:$I$101) )} -> 0 | N10: {=SUMPRODUCT( (MONTH($D$3:$D$101) = MONTH($K10)) * (YEAR($D$3:$D$101) = YEAR($K10)) * ($E$3:$E$101 = "Individual/Setor") * ($F$3:$F$101 = N$2) * ($I$3:$I$101) )} -> 0 | O10: {=SUMPRODUCT( (MONTH($D$3:$D$101) = MONTH($K10)) * (YEAR($D$3:$D$101) = YEAR($K10)) * ($E$3:$E$101 = "Individual/Setor") * ($F$3:$F$101 = O$2) * ($I$3:$I$101) )} -> 0 | P10: {=SUMPRODUCT( (MONTH($D$3:$D$101) = MONTH($K10)) * (YEAR($D$3:$D$101) = YEAR($K10)) * ($E$3:$E$101 = "Individual/Setor") * ($F$3:$F$101 = P$2) * ($I$3:$I$101) )} -> 0 | Q10: {=SUMPRODUCT( (MONTH($D$3:$D$101) = MONTH($K10)) * (YEAR($D$3:$D$101) = YEAR($K10)) * ($E$3:$E$101 = "Individual/Setor") * ($F$3:$F$101 = Q$2) * ($I$3:$I$101) )} -> 0 | R10: {=SUMPRODUCT( (MONTH($D$3:$D$101) = MONTH($K10)) * (YEAR($D$3:$D$101) = YEAR($K10)) * ($E$3:$E$101 = "Individual/Setor") * ($F$3:$F$101 = R$2) * ($I$3:$I$101) )} -> 0 | S10: {=SUMPRODUCT( (MONTH($D$3:$D$101) = MONTH($K10)) * (YEAR($D$3:$D$101) = YEAR($K10)) * ($E$3:$E$101 = "Individual/Setor") * ($F$3:$F$101 = S$2) * ($I$3:$I$101) )} -> 0 | T10: {=SUMPRODUCT( (MONTH($D$3:$D$101) = MONTH($K10)) * (YEAR($D$3:$D$101) = YEAR($K10)) * ($E$3:$E$101 = "Individual/Setor") * ($F$3:$F$101 = T$2) * ($I$3:$I$101) )} -> 0
A11: 45901 | B11: =SUMIFS(I:I, D:D, DATE(2025,9,1), E:E, "Estrutura") -> 0 | D11: 45870 | E11: Individual/Setor | F11: Luciane | G11: Estagiário | I11: 0 | K11: 45901 | L11: {=SUMPRODUCT( (MONTH($D$3:$D$101) = MONTH($K11)) * (YEAR($D$3:$D$101) = YEAR($K11)) * ($E$3:$E$101 = "Individual/Setor") * ($F$3:$F$101 = L$2) * ($I$3:$I$101) )} -> 0 | M11: {=SUMPRODUCT( (MONTH($D$3:$D$101) = MONTH($K11)) * (YEAR($D$3:$D$101) = YEAR($K11)) * ($E$3:$E$101 = "Individual/Setor") * ($F$3:$F$101 = M$2) * ($I$3:$I$101) )} -> 0 | N11: {=SUMPRODUCT( (MONTH($D$3:$D$101) = MONTH($K11)) * (YEAR($D$3:$D$101) = YEAR($K11)) * ($E$3:$E$101 = "Individual/Setor") * ($F$3:$F$101 = N$2) * ($I$3:$I$101) )} -> 0 | O11: {=SUMPRODUCT( (MONTH($D$3:$D$101) = MONTH($K11)) * (YEAR($D$3:$D$101) = YEAR($K11)) * ($E$3:$E$101 = "Individual/Setor") * ($F$3:$F$101 = O$2) * ($I$3:$I$101) )} -> 0 | P11: {=SUMPRODUCT( (MONTH($D$3:$D$101) = MONTH($K11)) * (YEAR($D$3:$D$101) = YEAR($K11)) * ($E$3:$E$101 = "Individual/Setor") * ($F$3:$F$101 = P$2) * ($I$3:$I$101) )} -> 0 | Q11: {=SUMPRODUCT( (MONTH($D$3:$D$101) = MONTH($K11)) * (YEAR($D$3:$D$101) = YEAR($K11)) * ($E$3:$E$101 = "Individual/Setor") * ($F$3:$F$101 = Q$2) * ($I$3:$I$101) )} -> 0 | R11: {=SUMPRODUCT( (MONTH($D$3:$D$101) = MONTH($K11)) * (YEAR($D$3:$D$101) = YEAR($K11)) * ($E$3:$E$101 = "Individual/Setor") * ($F$3:$F$101 = R$2) * ($I$3:$I$101) )} -> 0 | S11: {=SUMPRODUCT( (MONTH($D$3:$D$101) = MONTH($K11)) * (YEAR($D$3:$D$101) = YEAR($K11)) * ($E$3:$E$101 = "Individual/Setor") * ($F$3:$F$101 = S$2) * ($I$3:$I$101) )} -> 0 | T11: {=SUMPRODUCT( (MONTH($D$3:$D$101) = MONTH($K11)) * (YEAR($D$3:$D$101) = YEAR($K11)) * ($E$3:$E$101 = "Individual/Setor") * ($F$3:$F$101 = T$2) * ($I$3:$I$101) )} -> 0
A12: 45931 | B12: =SUMIFS(I:I, D:D, DATE(2025,10,1), E:E, "Estrutura") -> 0 | D12: 45689 | E12: Estrutura | F12: L&S | G12: Estagiário | I12: 0 | K12: 45931 | L12: {=SUMPRODUCT( (MONTH($D$3:$D$101) = MONTH($K12)) * (YEAR($D$3:$D$101) = YEAR($K12)) * ($E$3:$E$101 = "Individual/Setor") * ($F$3:$F$101 = L$2) * ($I$3:$I$101) )} -> 0 | M12: {=SUMPRODUCT( (MONTH($D$3:$D$101) = MONTH($K12)) * (YEAR($D$3:$D$101) = YEAR($K12)) * ($E$3:$E$101 = "Individual/Setor") * ($F$3:$F$101 = M$2) * ($I$3:$I$101) )} -> 0 | N12: {=SUMPRODUCT( (MONTH($D$3:$D$101) = MONTH($K12)) * (YEAR($D$3:$D$101) = YEAR($K12)) * ($E$3:$E$101 = "Individual/Setor") * ($F$3:$F$101 = N$2) * ($I$3:$I$101) )} -> 0 | O12: {=SUMPRODUCT( (MONTH($D$3:$D$101) = MONTH($K12)) * (YEAR($D$3:$D$101) = YEAR($K12)) * ($E$3:$E$101 = "Individual/Setor") * ($F$3:$F$101 = O$2) * ($I$3:$I$101) )} -> 0 | P12: {=SUMPRODUCT( (MONTH($D$3:$D$101) = MONTH($K12)) * (YEAR($D$3:$D$101) = YEAR($K12)) * ($E$3:$E$101 = "Individual/Setor") * ($F$3:$F$101 = P$2) * ($I$3:$I$101) )} -> 0 | Q12: {=SUMPRODUCT( (MONTH($D$3:$D$101) = MONTH($K12)) * (YEAR($D$3:$D$101) = YEAR($K12)) * ($E$3:$E$101 = "Individual/Setor") * ($F$3:$F$101 = Q$2) * ($I$3:$I$101) )} -> 0 | R12: {=SUMPRODUCT( (MONTH($D$3:$D$101) = MONTH($K12)) * (YEAR($D$3:$D$101) = YEAR($K12)) * ($E$3:$E$101 = "Individual/Setor") * ($F$3:$F$101 = R$2) * ($I$3:$I$101) )} -> 0 | S12: {=SUMPRODUCT( (MONTH($D$3:$D$101) = MONTH($K12)) * (YEAR($D$3:$D$101) = YEAR($K12)) * ($E$3:$E$101 = "Individual/Setor") * ($F$3:$F$101 = S$2) * ($I$3:$I$101) )} -> 0 | T12: {=SUMPRODUCT( (MONTH($D$3:$D$101) = MONTH($K12)) * (YEAR($D$3:$D$101) = YEAR($K12)) * ($E$3:$E$101 = "Individual/Setor") * ($F$3:$F$101 = T$2) * ($I$3:$I$101) )} -> 0
A13: 45962 | B13: =SUMIFS(I:I, D:D, DATE(2025,11,1), E:E, "Estrutura") -> 0 | I13: 0 | K13: 45962 | L13: {=SUMPRODUCT( (MONTH($D$3:$D$101) = MONTH($K13)) * (YEAR($D$3:$D$101) = YEAR($K13)) * ($E$3:$E$101 = "Individual/Setor") * ($F$3:$F$101 = L$2) * ($I$3:$I$101) )} -> 0 | M13: {=SUMPRODUCT( (MONTH($D$3:$D$101) = MONTH($K13)) * (YEAR($D$3:$D$101) = YEAR($K13)) * ($E$3:$E$101 = "Individual/Setor") * ($F$3:$F$101 = M$2) * ($I$3:$I$101) )} -> 0 | N13: {=SUMPRODUCT( (MONTH($D$3:$D$101) = MONTH($K13)) * (YEAR($D$3:$D$101) = YEAR($K13)) * ($E$3:$E$101 = "Individual/Setor") * ($F$3:$F$101 = N$2) * ($I$3:$I$101) )} -> 0 | O13: {=SUMPRODUCT( (MONTH($D$3:$D$101) = MONTH($K13)) * (YEAR($D$3:$D$101) = YEAR($K13)) * ($E$3:$E$101 = "Individual/Setor") * ($F$3:$F$101 = O$2) * ($I$3:$I$101) )} -> 0 | P13: {=SUMPRODUCT( (MONTH($D$3:$D$101) = MONTH($K13)) * (YEAR($D$3:$D$101) = YEAR($K13)) * ($E$3:$E$101 = "Individual/Setor") * ($F$3:$F$101 = P$2) * ($I$3:$I$101) )} -> 0 | Q13: {=SUMPRODUCT( (MONTH($D$3:$D$101) = MONTH($K13)) * (YEAR($D$3:$D$101) = YEAR($K13)) * ($E$3:$E$101 = "Individual/Setor") * ($F$3:$F$101 = Q$2) * ($I$3:$I$101) )} -> 0 | R13: {=SUMPRODUCT( (MONTH($D$3:$D$101) = MONTH($K13)) * (YEAR($D$3:$D$101) = YEAR($K13)) * ($E$3:$E$101 = "Individual/Setor") * ($F$3:$F$101 = R$2) * ($I$3:$I$101) )} -> 0 | S13: {=SUMPRODUCT( (MONTH($D$3:$D$101) = MONTH($K13)) * (YEAR($D$3:$D$101) = YEAR($K13)) * ($E$3:$E$101 = "Individual/Setor") * ($F$3:$F$101 = S$2) * ($I$3:$I$101) )} -> 0 | T13: {=SUMPRODUCT( (MONTH($D$3:$D$101) = MONTH($K13)) * (YEAR($D$3:$D$101) = YEAR($K13)) * ($E$3:$E$101 = "Individual/Setor") * ($F$3:$F$101 = T$2) * ($I$3:$I$101) )} -> 0
A14: 45992 | B14: =SUMIFS(I:I, D:D, DATE(2025,12,1), E:E, "Estrutura") -> 0 | I14: 0 | K14: 45992 | L14: {=SUMPRODUCT( (MONTH($D$3:$D$101) = MONTH($K14)) * (YEAR($D$3:$D$101) = YEAR($K14)) * ($E$3:$E$101 = "Individual/Setor") * ($F$3:$F$101 = L$2) * ($I$3:$I$101) )} -> 0 | M14: {=SUMPRODUCT( (MONTH($D$3:$D$101) = MONTH($K14)) * (YEAR($D$3:$D$101) = YEAR($K14)) * ($E$3:$E$101 = "Individual/Setor") * ($F$3:$F$101 = M$2) * ($I$3:$I$101) )} -> 0 | N14: {=SUMPRODUCT( (MONTH($D$3:$D$101) = MONTH($K14)) * (YEAR($D$3:$D$101) = YEAR($K14)) * ($E$3:$E$101 = "Individual/Setor") * ($F$3:$F$101 = N$2) * ($I$3:$I$101) )} -> 0 | O14: {=SUMPRODUCT( (MONTH($D$3:$D$101) = MONTH($K14)) * (YEAR($D$3:$D$101) = YEAR($K14)) * ($E$3:$E$101 = "Individual/Setor") * ($F$3:$F$101 = O$2) * ($I$3:$I$101) )} -> 0 | P14: {=SUMPRODUCT( (MONTH($D$3:$D$101) = MONTH($K14)) * (YEAR($D$3:$D$101) = YEAR($K14)) * ($E$3:$E$101 = "Individual/Setor") * ($F$3:$F$101 = P$2) * ($I$3:$I$101) )} -> 0 | Q14: {=SUMPRODUCT( (MONTH($D$3:$D$101) = MONTH($K14)) * (YEAR($D$3:$D$101) = YEAR($K14)) * ($E$3:$E$101 = "Individual/Setor") * ($F$3:$F$101 = Q$2) * ($I$3:$I$101) )} -> 0 | R14: {=SUMPRODUCT( (MONTH($D$3:$D$101) = MONTH($K14)) * (YEAR($D$3:$D$101) = YEAR($K14)) * ($E$3:$E$101 = "Individual/Setor") * ($F$3:$F$101 = R$2) * ($I$3:$I$101) )} -> 0 | S14: {=SUMPRODUCT( (MONTH($D$3:$D$101) = MONTH($K14)) * (YEAR($D$3:$D$101) = YEAR($K14)) * ($E$3:$E$101 = "Individual/Setor") * ($F$3:$F$101 = S$2) * ($I$3:$I$101) )} -> 0 | T14: {=SUMPRODUCT( (MONTH($D$3:$D$101) = MONTH($K14)) * (YEAR($D$3:$D$101) = YEAR($K14)) * ($E$3:$E$101 = "Individual/Setor") * ($F$3:$F$101 = T$2) * ($I$3:$I$101) )} -> 0
A15: Total | B15: =SUM(B3:B14) -> 0 | I15: 0
I16: 0
I17: 0
I18: 0

Sheet Lançamentos Contábeis
A1: Data | B1: Conta Débito | C1: Conta Crédito | D1: Valor (R$) | E1: Histórico
A2: 45620 | B2: Equipamentos / Móveis | C2: Capital Social | D2: 2000 | E2: Integralização
A3: 45826 | B3: Caixa e Bancos | C3: Receita de Honorários | D3: 1500 | E3: Rodrigo Velho de Almeida
A4: 45826 | B4: Receita de Honorários | C4: Pró-labore | D4: 553.04 | E4: André
A5: 45826 | B5: Receita de Honorários | C5: Impostos e Contribuições | D5: 260.14
A6: 45826 | B6: Impostos e Contribuições | C6: Obrigações Fiscais (Simples, INSS) | D6: 67.51 | E6: Simples
A7: 45826 | B7: Impostos e Contribuições | C7: Obrigações Fiscais (Simples, INSS) | D7: 124.28 | E7: INSS Patronal
A8: 45826 | B8: Impostos e Contribuições | C8: Obrigações Fiscais (Simples, INSS) | D8: 68.35 | E8: INSS Individual
A9: 45826 | B9: Pró-labore | C9: Reserva de Lucros | D9: 553.04 | E9: André
A10: 45826 | B10: Receita de Honorários | C10: Reserva de Lucros | D10: 130.82 | E10: Fundo
A11: 45826 | B11: Receita de Honorários | C11: Reserva de Lucros | D11: 556 | E11: Bruna
A12: 45826 | B12: Reserva de Lucros | C12: Caixa e Bancos | D12: 556 | E12: Bruna - Pagamento
A13: 45826 | B13: Reserva de Lucros | C13: Fundo de Reserva | D13: 130.82 | E13: Fundo
A14: 45839 | B14: Obrigações Fiscais (Simples, INSS) | C14: Caixa e Bancos | D14: 67.51 | E14: Simples
A15: 45840 | B15: Reserva de Lucros | C15: Caixa e Bancos | D15: 553.04 | E15: André - Pagamento
A17: 45864 | B17: Caixa e Bancos | C17: Receita de Honorários | D17: 330 | E17: Taiana Lopes
A18: 45874 | B18: Obrigações Fiscais (Simples, INSS) | C18: Caixa e Bancos | D18: 192.62 | E18: DARF - INSS
... A20: 45874 | B20: Receita de Honorários | C20: Pró-labore | D20: 213.92 | E20: André
A21: 45874 | B21: Receita de Honorários | C21: Reserva de Lucros | D21: 28.71
A22: 45874 | B22: Impostos e Contribuições | C22: Obrigações Fiscais (Simples, INSS) | D22: 48.07 | E22: INSS Patronal
A23: 45874 | B23: Impostos e Contribuições | C23: Obrigações Fiscais (Simples, INSS) | D23: 26.44 | E23: INSS Individual
A24: 45874 | B24: Impostos e Contribuições | C24: Obrigações Fiscais (Simples, INSS) | D24: 14.85 | E24: Simples
A25: 45874 | B25: Pró-labore | C25: Reserva de Lucros | D25: 213.92 | E25: André
A26: 45874 | B26: Reserva de Lucros | C26: Caixa e Bancos | D26: 213.92 | E26: André - Pagamento
A27: 45874 | B27: Reserva de Lucros | C27: Fundo de Reserva | D27: 28.71 | E27: 10% do Mês de Julho + Lucro da Caixinha
A28: 45874 | B28: Obrigações Fiscais (Simples, INSS) | C28: Caixa e Bancos | D28: 14.85 | E28: Simples
A30: 45897 | B30: Caixa e Bancos | C30: Receita de Honorários | D30: 330 | E30: Taiana Lopes
A31: 45901 | B31: Receita de Honorários | C31: Pró-labore | D31: 213.92 | E31: André
A32: 45901 | B32: Receita de Honorários | C32: Reserva de Lucros | D32: 26.71
A33: 45901 | B33: Impostos e Contribuições | C33: Obrigações Fiscais (Simples, INSS) | D33: 48.07 | E33: INSS Patronal
A34: 45901 | B34: Impostos e Contribuições | C34: Obrigações Fiscais (Simples, INSS) | D34: 26.43 | E34: INSS Individual
A35: 45901 | B35: Impostos e Contribuições | C35: Obrigações Fiscais (Simples, INSS) | D35: 14.85 | E35: Simples
A36: 45901 | B36: Obrigações Fiscais (Simples, INSS) | C36: Caixa e Bancos | D36: 14.85 | E36: Simples
A37: 45901 | B37: Obrigações Fiscais (Simples, INSS) | C37: Caixa e Bancos | D37: 74.51 | E37: DARF - INSS
A38: 45901 | B38: Pró-labore | C38: Reserva de Lucros | D38: 213.92 | E38: André
A39: 45901 | B39: Reserva de Lucros | C39: Caixa e Bancos | D39: 213.92 | E39: André - Pagamento
A40: 45901 | B40: Reserva de Lucros | C40: Fundo de Reserva | D40: 26.71 | E40: 10% do Mês de Agosto
A41: 45943 | B41: Caixa e Bancos | C41: Receita de Honorários | D41: 1.6 | E41: Lucro Retirado - Caixinha Nubank
A42: 45943 | B42: Receita de Honorários | C42: Reserva de Lucros | D42: 1.6 | E42: Lucro Retirado - Caixinha Nubank
A43: 45943 | B43: Reserva de Lucros | C43: Fundo de Reserva | D43: 1.6 | E43: Lucro Retirado - Caixinha Nubank
...

Sheet Plano de Contas
A1: Código | B1: Conta contábil | C1: Natureza | D1: Tipo | F1: Débito | G1: Crédito
A2: 1.1 | B2: Caixa e Bancos | C2: Ativo | D2: Circulante | F2: Caixa e Bancos | G2: Caixa e Bancos | I2: Ativo
A3: 1.2 | B3: Clientes (honorários a receber) | C3: Ativo | D3: Circulante | F3: Clientes (honorários a receber) | G3: Clientes (honorários a receber) | I3: Passivo
A4: 1.3 | B4: Adiantamentos a sócios | C4: Ativo | D4: Circulante | F4: Adiantamentos a sócios | G4: Fornecedores / Contas a pagar | I4: Receita
A5: 1.4 | B5: Equipamentos / Móveis | C5: Ativo | D5: Circulante | F5: Equipamentos / Móveis | G5: Obrigações Fiscais (Simples, INSS) | I5: Despesa
A6: 2.1 | B6: Fornecedores / Contas a pagar | C6: Passivo | D6: Circulante | F6: Obrigações Fiscais (Simples, INSS) | G6: Pró-labore
A7: 2.2 | B7: Obrigações Fiscais (Simples, INSS) | C7: Passivo | D7: Circulante | F7: Pró-labore | G7: Capital Social
A8: 2.3 | B8: Pró-labore | C8: Passivo | D8: Circulante | F8: Reserva de Lucros | G8: Reserva de Lucros
A9: 3.1 | B9: Capital Social | C9: Patrimônio Líquido | D9: Permanente | F9: Fundo de Reserva | G9: Fundo de Reserva
A10: 3.2 | B10: Reserva de Lucros | C10: Patrimônio Líquido | D10: Permanente | F10: Lucros Distribuídos | G10: Receita de Honorários
A11: 3.3 | B11: Fundo de Reserva | C11: Patrimônio Líquido | D11: Permanente | F11: Receita de Honorários | G11: Lucros Distribuídos
A12: 3.4 | B12: Lucros Distribuídos | C12: Patrimônio Líquido | D12: Permanente | F12: Despesas com Pessoal | G12: Despesas com Pessoal
A13: 4.1 | B13: Receita de Honorários | C13: Receita | D13: Operacional | F13: Despesas Administrativas | G13: Despesas Administrativas
A14: 5.1 | B14: Despesas com Pessoal | C14: Despesa | D14: Operacional | F14: Impostos e Contribuições | G14: Impostos e Contribuições
A15: 5.2 | B15: Despesas Administrativas | C15: Despesa | D15: Operacional
A16: 5.3 | B16: Impostos e Contribuições | C16: Despesa | D16: Operacional
B18: SALDOS
A19: Código | B19: Conta | C19: Natureza | D19: Total Débito | E19: Total Crédito | F19: Saldo
A20: 1.1 | B20: Caixa e Bancos | C20: Ativo | D20: {=SUMPRODUCT( ('Lançamentos Contábeis'!$B$2:$B$999=B20) * ('Lançamentos Contábeis'!$A$2:$A$999<=Configuração!$C$2) * ('Lançamentos Contábeis'!$D$2:$D$999) )} -> 2663.6 | E20: {=SUMPRODUCT( ('Lançamentos Contábeis'!$C$2:$C$999=B20) * ('Lançamentos Contábeis'!$A$2:$A$999<=Configuração!$C$2) * ('Lançamentos Contábeis'!$D$2:$D$999) )} -> 1975.73 | F20: =IF(C20="Ativo", D20 - E20, E20 - D20) -> 687.87
A21: 1.2 | B21: Clientes (honorários a receber) | C21: Ativo | D21: {=SUMPRODUCT( ('Lançamentos Contábeis'!$B$2:$B$999=B21) * ('Lançamentos Contábeis'!$A$2:$A$999<=Configuração!$C$2) * ('Lançamentos Contábeis'!$D$2:$D$999) )} -> 0 | E21: {=SUMPRODUCT( ('Lançamentos Contábeis'!$C$2:$C$999=B21) * ('Lançamentos Contábeis'!$A$2:$A$999<=Configuração!$C$2) * ('Lançamentos Contábeis'!$D$2:$D$999) )} -> 0 | F21: =IF(C21="Ativo", D21 - E21, E21 - D21) -> 0
A22: 1.3 | B22: Adiantamentos a sócios | C22: Ativo | D22: {=SUMPRODUCT( ('Lançamentos Contábeis'!$B$2:$B$999=B22) * ('Lançamentos Contábeis'!$A$2:$A$999<=Configuração!$C$2) * ('Lançamentos Contábeis'!$D$2:$D$999) )} -> 0 | E22: {=SUMPRODUCT( ('Lançamentos Contábeis'!$C$2:$C$999=B22) * ('Lançamentos Contábeis'!$A$2:$A$999<=Configuração!$C$2) * ('Lançamentos Contábeis'!$D$2:$D$999) )} -> 0 | F22: =IF(C22="Ativo", D22 - E22, E22 - D22) -> 0
A23: 1.4 | B23: Equipamentos / Móveis | C23: Ativo | D23: {=SUMPRODUCT( ('Lançamentos Contábeis'!$B$2:$B$999=B23) * ('Lançamentos Contábeis'!$A$2:$A$999<=Configuração!$C$2) * ('Lançamentos Contábeis'!$D$2:$D$999) )} -> 2000 | E23: {=SUMPRODUCT( ('Lançamentos Contábeis'!$C$2:$C$999=B23) * ('Lançamentos Contábeis'!$A$2:$A$999<=Configuração!$C$2) * ('Lançamentos Contábeis'!$D$2:$D$999) )} -> 0 | F23: =IF(C23="Ativo", D23 - E23, E23 - D23) -> 2000
A24: 2.1 | B24: Fornecedores / Contas a pagar | C24: Passivo | D24: {=SUMPRODUCT( ('Lançamentos Contábeis'!$B$2:$B$999=B24) * ('Lançamentos Contábeis'!$A$2:$A$999<=Configuração!$C$2) * ('Lançamentos Contábeis'!$D$2:$D$999) )} -> 0 | E24: {=SUMPRODUCT( ('Lançamentos Contábeis'!$C$2:$C$999=B24) * ('Lançamentos Contábeis'!$A$2:$A$999<=Configuração!$C$2) * ('Lançamentos Contábeis'!$D$2:$D$999) )} -> 0 | F24: =IF(C24="Ativo", D24 - E24, E24 - D24) -> 0
A25: 2.2 | B25: Obrigações Fiscais (Simples, INSS) | C25: Passivo | D25: {=SUMPRODUCT( ('Lançamentos Contábeis'!$B$2:$B$999=B25) * ('Lançamentos Contábeis'!$A$2:$A$999<=Configuração!$C$2) * ('Lançamentos Contábeis'!$D$2:$D$999) )} -> 438.85 | E25: {=SUMPRODUCT( ('Lançamentos Contábeis'!$C$2:$C$999=B25) * ('Lançamentos Contábeis'!$A$2:$A$999<=Configuração!$C$2) * ('Lançamentos Contábeis'!$D$2:$D$999) )} -> 438.85 | F25: =IF(C25="Ativo", D25 - E25, E25 - D25) -> 0
A26: 2.3 | B26: Pró-labore | C26: Passivo | D26: {=SUMPRODUCT( ('Lançamentos Contábeis'!$B$2:$B$999=B26) * ('Lançamentos Contábeis'!$A$2:$A$999<=Configuração!$C$2) * ('Lançamentos Contábeis'!$D$2:$D$999) )} -> 980.88 | E26: {=SUMPRODUCT( ('Lançamentos Contábeis'!$C$2:$C$999=B26) * ('Lançamentos Contábeis'!$A$2:$A$999<=Configuração!$C$2) * ('Lançamentos Contábeis'!$D$2:$D$999) )} -> 980.88 | F26: =IF(C26="Ativo", D26 - E26, E26 - D26) -> 0
A27: 3.1 | B27: Capital Social | C27: Patrimônio Líquido | D27: {=SUMPRODUCT( ('Lançamentos Contábeis'!$B$2:$B$999=B27) * ('Lançamentos Contábeis'!$A$2:$A$999<=Configuração!$C$2) * ('Lançamentos Contábeis'!$D$2:$D$999) )} -> 0 | E27: {=SUMPRODUCT( ('Lançamentos Contábeis'!$C$2:$C$999=B27) * ('Lançamentos Contábeis'!$A$2:$A$999<=Configuração!$C$2) * ('Lançamentos Contábeis'!$D$2:$D$999) )} -> 2400 | F27: =IF(C27="Ativo", D27 - E27, E27 - D27) -> 2400
A28: 3.2 | B28: Reserva de Lucros | C28: Patrimônio Líquido | D28: {=SUMPRODUCT( ('Lançamentos Contábeis'!$B$2:$B$999=B28) * ('Lançamentos Contábeis'!$A$2:$A$999<=Configuração!$C$2) * ('Lançamentos Contábeis'!$D$2:$D$999) )} -> 1724.72 | E28: {=SUMPRODUCT( ('Lançamentos Contábeis'!$C$2:$C$999=B28) * ('Lançamentos Contábeis'!$A$2:$A$999<=Configuração!$C$2) * ('Lançamentos Contábeis'!$D$2:$D$999) )} -> 1824.72 | F28: =IF(C28="Ativo", D28 - E28, E28 - D28) -> 100
A29: 3.3 | B29: Fundo de Reserva | C29: Patrimônio Líquido | D29: {=SUMPRODUCT( ('Lançamentos Contábeis'!$B$2:$B$999=B29) * ('Lançamentos Contábeis'!$A$2:$A$999<=Configuração!$C$2) * ('Lançamentos Contábeis'!$D$2:$D$999) )} -> 0 | E29: {=SUMPRODUCT( ('Lançamentos Contábeis'!$C$2:$C$999=B29) * ('Lançamentos Contábeis'!$A$2:$A$999<=Configuração!$C$2) * ('Lançamentos Contábeis'!$D$2:$D$999) )} -> 187.84 | F29: =IF(C29="Ativo", D29 - E29, E29 - D29) -> 187.84
A30: 3.4 | B30: Lucros Distribuídos | C30: Patrimônio Líquido | D30: {=SUMPRODUCT( ('Lançamentos Contábeis'!$B$2:$B$999=B30) * ('Lançamentos Contábeis'!$A$2:$A$999<=Configuração!$C$2) * ('Lançamentos Contábeis'!$D$2:$D$999) )} -> 0 | E30: {=SUMPRODUCT( ('Lançamentos Contábeis'!$C$2:$C$999=B30) * ('Lançamentos Contábeis'!$A$2:$A$999<=Configuração!$C$2) * ('Lançamentos Contábeis'!$D$2:$D$999) )} -> 0 | F30: =IF(C30="Ativo", D30 - E30, E30 - D30) -> 0
A31: 4.1 | B31: Receita de Honorários | C31: Receita | D31: {=SUMPRODUCT(--('Lançamentos Contábeis'!$B$2:$B$999=B31), --('Lançamentos Contábeis'!$A$2:$A$999>=Configuração!$C$1), --('Lançamentos Contábeis'!$A$2:$A$999<=Configuração!$C$2), 'Lançamentos Contábeis'!$D$2:$D$999)} -> 100 | E31: {=SUMPRODUCT(--('Lançamentos Contábeis'!$C$2:$C$999=B31), --('Lançamentos Contábeis'!$A$2:$A$999>=Configuração!$C$1), --('Lançamentos Contábeis'!$A$2:$A$999<=Configuração!$C$2), 'Lançamentos Contábeis'!$D$2:$D$999)} -> 100 | F31: =IF(C31="Ativo", D31 - E31, E31 - D31) -> 0
A32: 5.1 | B32: Despesas com Pessoal | C32: Despesa | D32: {=SUMPRODUCT(--('Lançamentos Contábeis'!$B$2:$B$999=B32), --('Lançamentos Contábeis'!$A$2:$A$999>=Configuração!$C$1), --('Lançamentos Contábeis'!$A$2:$A$999<=Configuração!$C$2), 'Lançamentos Contábeis'!$D$2:$D$999)} -> 0 | E32: {=SUMPRODUCT(--('Lançamentos Contábeis'!$C$2:$C$999=B32), --('Lançamentos Contábeis'!$A$2:$A$999>=Configuração!$C$1), --('Lançamentos Contábeis'!$A$2:$A$999<=Configuração!$C$2), 'Lançamentos Contábeis'!$D$2:$D$999)} -> 0 | F32: =IF(C32="Despesa", D32 - E32, E32 - D32) -> 0
A33: 5.2 | B33: Despesas Administrativas | C33: Despesa | D33: {=SUMPRODUCT(--('Lançamentos Contábeis'!$B$2:$B$999=B33), --('Lançamentos Contábeis'!$A$2:$A$999>=Configuração!$C$1), --('Lançamentos Contábeis'!$A$2:$A$999<=Configuração!$C$2), 'Lançamentos Contábeis'!$D$2:$D$999)} -> 0 | E33: {=SUMPRODUCT(--('Lançamentos Contábeis'!$C$2:$C$999=B33), --('Lançamentos Contábeis'!$A$2:$A$999>=Configuração!$C$1), --('Lançamentos Contábeis'!$A$2:$A$999<=Configuração!$C$2), 'Lançamentos Contábeis'!$D$2:$D$999)} -> 0 | F33: =IF(C33="Despesa", D33 - E33, E33 - D33) -> 0
A34: 5.3 | B34: Impostos e Contribuições | C34: Despesa | D34: {=SUMPRODUCT(--('Lançamentos Contábeis'!$B$2:$B$999=B34), --('Lançamentos Contábeis'!$A$2:$A$999>=Configuração!$C$1), --('Lançamentos Contábeis'!$A$2:$A$999<=Configuração!$C$2), 'Lançamentos Contábeis'!$D$2:$D$999)} -> 0 | E34: {=SUMPRODUCT(--('Lançamentos Contábeis'!$C$2:$C$999=B34), --('Lançamentos Contábeis'!$A$2:$A$999>=Configuração!$C$1), --('Lançamentos Contábeis'!$A$2:$A$999<=Configuração!$C$2), 'Lançamentos Contábeis'!$D$2:$D$999)} -> 0 | F34: =IF(C34="Despesa", D34 - E34, E34 - D34) -> 0

Sheet Balanço
A1: Classe | B1: Conta | C1: Saldo
A2: Ativo | B2: Caixa e Bancos | C2: =VLOOKUP("Caixa e Bancos", 'Plano de Contas'!$B$20:$F$101, 5, FALSE) -> 687.87
B3: Clientes (honorários a receber) | C3: =VLOOKUP("Clientes (honorários a receber)", 'Plano de Contas'!$B$20:$F$101, 5, FALSE) -> 0
B4: Adiantamentos a sócios | C4: =VLOOKUP("Adiantamentos a sócios", 'Plano de Contas'!$B$20:$F$101, 5, FALSE) -> 0
B5: Equipamentos / Móveis | C5: =VLOOKUP("Equipamentos / Móveis", 'Plano de Contas'!$B$20:$F$101, 5, FALSE) -> 2000
A6: Total do Ativo | C6: =SUM(C2:C5) -> 2687.87
A7: Passivo | B7: Fornecedores / Contas a pagar | C7: =VLOOKUP("Fornecedores / Contas a pagar", 'Plano de Contas'!$B$20:$F$101, 5, FALSE) -> 0
B8: Obrigações Fiscais (Simples, INSS) | C8: =VLOOKUP("Obrigações Fiscais (Simples, INSS)", 'Plano de Contas'!$B$20:$F$101, 5, FALSE) -> 0
B9: Pró-labore | C9: =VLOOKUP("Pró-labore", 'Plano de Contas'!$B$20:$F$101, 5, FALSE) -> 0
A10: Total Passivo | C10: =SUM(C7:C9) -> 0
A11: Patrimônio Líquido | B11: Capital Social | C11: =VLOOKUP("Capital Social", 'Plano de Contas'!$B$20:$F$101, 5, FALSE) -> 2400
B12: Reserva de Lucros | C12: =VLOOKUP("Reserva de Lucros", 'Plano de Contas'!$B$20:$F$101, 5, FALSE) -> 100
B13: Fundo de Reserva | C13: =VLOOKUP("Fundo de Reserva", 'Plano de Contas'!$B$20:$F$101, 5, FALSE) -> 187.84
B14: Lucros Distribuídos | C14: =VLOOKUP("Lucros Distribuídos", 'Plano de Contas'!$B$20:$F$101, 5, FALSE) -> 0
A15: Total Passivo + PL | C15: =SUM(C11:C14)-(C10) -> 2687.84

Sheet Pró-labore
A1: PRÓ-LABORE E LUCRO LÍQUIDO ANDRÉ
A2: Mês | B2: Nome | C2: Tipo | D2: Valor Bruto | E2: INSS (Pessoa) | F2: INSS (Patronal) | G2: IRPF | H2: Pró-Labore Líquido | I2: Lucro André (líquido) | J2: Total
A3: 45658 | B3: André Savio | C3: Administrador | D3: {=MIN(1518, SUMPRODUCT( (MONTH('Lucros Disponíveis'!$A$2:$A$1000)=MONTH(A3)) * (YEAR('Lucros Disponíveis'!$A$2:$A$1000)=YEAR(A3)) * ('Lucros Disponíveis'!$B$2:$B$1000 + 'Lucros Disponíveis'!$D$2:$D$1000) ) )} -> 0 | E3: =IF(D3="", "", D3*11%) -> 0 | F3: =IF(D3="", "", D3*20%) -> 0 | H3: =IF(D3="", "", D3 -E3) -> 0 | I3: =IF( ('Lucros Disponíveis'!B2 + 'Lucros Disponíveis'!D2 > D3), ('Lucros Disponíveis'!B2 + 'Lucros Disponíveis'!D2 - D3), H3 ) -> 0 | J3: =IF(I3=H3, H3, H3+I3) -> 0
A4: 45689 | B4: André Savio | C4: Administrador | D4: {=MIN(1518, SUMPRODUCT( (MONTH('Lucros Disponíveis'!$A$2:$A$1000)=MONTH(A4)) * (YEAR('Lucros Disponíveis'!$A$2:$A$1000)=YEAR(A4)) * ('Lucros Disponíveis'!$B$2:$B$1000 + 'Lucros Disponíveis'!$D$2:$D$1000) ) )} -> 0 | E4: =IF(D4="", "", D4*11%) -> 0 | F4: =IF(D4="", "", D4*20%) -> 0 | H4: =IF(D4="", "", D4 -E4) -> 0 | I4: =IF( ('Lucros Disponíveis'!B3 + 'Lucros Disponíveis'!D3 > D4), ('Lucros Disponíveis'!B3 + 'Lucros Disponíveis'!D3 - D4), H4 ) -> 0 | J4: =IF(I4=H4, H4, H4+I4) -> 0
A5: 45717 | B5: André Savio | C5: Administrador | D5: {=MIN(1518, SUMPRODUCT( (MONTH('Lucros Disponíveis'!$A$2:$A$1000)=MONTH(A5)) * (YEAR('Lucros Disponíveis'!$A$2:$A$1000)=YEAR(A5)) * ('Lucros Disponíveis'!$B$2:$B$1000 + 'Lucros Disponíveis'!$D$2:$D$1000) ) )} -> 0 | E5: =IF(D5="", "", D5*11%) -> 0 | F5: =IF(D5="", "", D5*20%) -> 0 | H5: =IF(D5="", "", D5 -E5) -> 0 | I5: =IF( ('Lucros Disponíveis'!B4 + 'Lucros Disponíveis'!D4 > D5), ('Lucros Disponíveis'!B4 + 'Lucros Disponíveis'!D4 - D5), H5 ) -> 0 | J5: =IF(I5=H5, H5, H5+I5) -> 0
A6: 45748 | B6: André Savio | C6: Administrador | D6: {=MIN(1518, SUMPRODUCT( (MONTH('Lucros Disponíveis'!$A$2:$A$1000)=MONTH(A6)) * (YEAR('Lucros Disponíveis'!$A$2:$A$1000)=YEAR(A6)) * ('Lucros Disponíveis'!$B$2:$B$1000 + 'Lucros Disponíveis'!$D$2:$D$1000) ) )} -> 0 | E6: =IF(D6="", "", D6*11%) -> 0 | F6: =IF(D6="", "", D6*20%) -> 0 | H6: =IF(D6="", "", D6 -E6) -> 0 | I6: =IF( ('Lucros Disponíveis'!B5 + 'Lucros Disponíveis'!D5 > D6), ('Lucros Disponíveis'!B5 + 'Lucros Disponíveis'!D5 - D6), H6 ) -> 0 | J6: =IF(I6=H6, H6, H6+I6) -> 0
A7: 45778 | B7: André Savio | C7: Administrador | D7: {=MIN(1518, SUMPRODUCT( (MONTH('Lucros Disponíveis'!$A$2:$A$1000)=MONTH(A7)) * (YEAR('Lucros Disponíveis'!$A$2:$A$1000)=YEAR(A7)) * ('Lucros Disponíveis'!$B$2:$B$1000 + 'Lucros Disponíveis'!$D$2:$D$1000) ) )} -> 0 | E7: =IF(D7="", "", D7*11%) -> 0 | F7: =IF(D7="", "", D7*20%) -> 0 | H7: =IF(D7="", "", D7 -E7) -> 0 | I7: =IF( ('Lucros Disponíveis'!B6 + 'Lucros Disponíveis'!D6 > D7), ('Lucros Disponíveis'!B6 + 'Lucros Disponíveis'!D6 - D7), H7 ) -> 0 | J7: =IF(I7=H7, H7, H7+I7) -> 0
A8: 45809 | B8: André Savio | C8: Administrador | D8: {=MIN(1518, SUMPRODUCT( (MONTH('Lucros Disponíveis'!$A$2:$A$1000)=MONTH(A8)) * (YEAR('Lucros Disponíveis'!$A$2:$A$1000)=YEAR(A8)) * ('Lucros Disponíveis'!$B$2:$B$1000 + 'Lucros Disponíveis'!$D$2:$D$1000) ) )} -> 621.40411 | E8: =IF(D8="", "", D8*11%) -> 68.354452 | F8: =IF(D8="", "", D8*20%) -> 124.28082 | H8: =IF(D8="", "", D8 -E8) -> 553.04966 | I8: =IF( ('Lucros Disponíveis'!B7 + 'Lucros Disponíveis'!D7 > D8), ('Lucros Disponíveis'!B7 + 'Lucros Disponíveis'!D7 - D8), H8 ) -> 553.04966 | J8: =IF(I8=H8, H8, H8+I8) -> 553.04966
A9: 45839 | B9: André Savio | C9: Administrador | D9: {=MIN(1518, SUMPRODUCT( (MONTH('Lucros Disponíveis'!$A$2:$A$1000)=MONTH(A9)) * (YEAR('Lucros Disponíveis'!$A$2:$A$1000)=YEAR(A9)) * ('Lucros Disponíveis'!$B$2:$B$1000 + 'Lucros Disponíveis'!$D$2:$D$1000) ) )} -> 240.36864 | E9: =IF(D9="", "", D9*11%) -> 26.440551 | F9: =IF(D9="", "", D9*20%) -> 48.073729 | H9: =IF(D9="", "", D9 -E9) -> 213.92809 | I9: =IF( ('Lucros Disponíveis'!B8 + 'Lucros Disponíveis'!D8 > D9), ('Lucros Disponíveis'!B8 + 'Lucros Disponíveis'!D8 - D9), H9 ) -> 213.92809 | J9: =IF(I9=H9, H9, H9+I9) -> 213.92809
A10: 45870 | B10: André Savio | C10: Administrador | D10: {=MIN(1518, SUMPRODUCT( (MONTH('Lucros Disponíveis'!$A$2:$A$1000)=MONTH(A10)) * (YEAR('Lucros Disponíveis'!$A$2:$A$1000)=YEAR(A10)) * ('Lucros Disponíveis'!$B$2:$B$1000 + 'Lucros Disponíveis'!$D$2:$D$1000) ) )} -> 240.36864 | E10: =IF(D10="", "", D10*11%) -> 26.440551 | F10: =IF(D10="", "", D10*20%) -> 48.073729 | H10: =IF(D10="", "", D10 -E10) -> 213.92809 | I10: =IF( ('Lucros Disponíveis'!B9 + 'Lucros Disponíveis'!D9 > D10), ('Lucros Disponíveis'!B9 + 'Lucros Disponíveis'!D9 - D10), H10 ) -> 213.92809 | J10: =IF(I10=H10, H10, H10+I10) -> 213.92809
A11: 45901 | B11: André Savio | C11: Administrador | D11: {=MIN(1518, SUMPRODUCT( (MONTH('Lucros Disponíveis'!$A$2:$A$1000)=MONTH(A11)) * (YEAR('Lucros Disponíveis'!$A$2:$A$1000)=YEAR(A11)) * ('Lucros Disponíveis'!$B$2:$B$1000 + 'Lucros Disponíveis'!$D$2:$D$1000) ) )} -> 0 | E11: =IF(D11="", "", D11*11%) -> 0 | F11: =IF(D11="", "", D11*20%) -> 0 | H11: =IF(D11="", "", D11 -E11) -> 0 | I11: =IF( ('Lucros Disponíveis'!B10 + 'Lucros Disponíveis'!D10 > D11), ('Lucros Disponíveis'!B10 + 'Lucros Disponíveis'!D10 - D11), H11 ) -> 0 | J11: =IF(I11=H11, H11, H11+I11) -> 0
A12: 45931 | B12: André Savio | C12: Administrador | D12: {=MIN(1518, SUMPRODUCT( (MONTH('Lucros Disponíveis'!$A$2:$A$1000)=MONTH(A12)) * (YEAR('Lucros Disponíveis'!$A$2:$A$1000)=YEAR(A12)) * ('Lucros Disponíveis'!$B$2:$B$1000 + 'Lucros Disponíveis'!$D$2:$D$1000) ) )} -> 0 | E12: =IF(D12="", "", D12*11%) -> 0 | F12: =IF(D12="", "", D12*20%) -> 0 | H12: =IF(D12="", "", D12 -E12) -> 0 | I12: =IF( ('Lucros Disponíveis'!B11 + 'Lucros Disponíveis'!D11 > D12), ('Lucros Disponíveis'!B11 + 'Lucros Disponíveis'!D11 - D12), H12 ) -> 0 | J12: =IF(I12=H12, H12, H12+I12) -> 0
A13: 45962 | B13: André Savio | C13: Administrador | D13: {=MIN(1518, SUMPRODUCT( (MONTH('Lucros Disponíveis'!$A$2:$A$1000)=MONTH(A13)) * (YEAR('Lucros Disponíveis'!$A$2:$A$1000)=YEAR(A13)) * ('Lucros Disponíveis'!$B$2:$B$1000 + 'Lucros Disponíveis'!$D$2:$D$1000) ) )} -> 301.45372 | E13: =IF(D13="", "", D13*11%) -> 33.159909 | F13: =IF(D13="", "", D13*20%) -> 60.290744 | H13: =IF(D13="", "", D13 -E13) -> 268.29381 | I13: =IF( ('Lucros Disponíveis'!B12 + 'Lucros Disponíveis'!D12 > D13), ('Lucros Disponíveis'!B12 + 'Lucros Disponíveis'!D12 - D13), H13 ) -> 268.29381 | J13: =IF(I13=H13, H13, H13+I13) -> 268.29381
A14: 45992 | B14: André Savio | C14: Administrador | D14: {=MIN(1518, SUMPRODUCT( (MONTH('Lucros Disponíveis'!$A$2:$A$1000)=MONTH(A14)) * (YEAR('Lucros Disponíveis'!$A$2:$A$1000)=YEAR(A14)) * ('Lucros Disponíveis'!$B$2:$B$1000 + 'Lucros Disponíveis'!$D$2:$D$1000) ) )} -> 0 | E14: =IF(D14="", "", D14*11%) -> 0 | F14: =IF(D14="", "", D14*20%) -> 0 | H14: =IF(D14="", "", D14 -E14) -> 0 | I14: =IF( ('Lucros Disponíveis'!B13 + 'Lucros Disponíveis'!D13 > D14), ('Lucros Disponíveis'!B13 + 'Lucros Disponíveis'!D13 - D14), H14 ) -> 0 | J14: =IF(I14=H14, H14, H14+I14) -> 0
A17: ASSOCIADA
A18: Mês | B18: Nome | C18: Tipo | D18: Valor Bruto | E18: INSS (Pessoa) | F18: INSS (Patronal) | G18: IRPF | H18: Pró-Labore Líquido
A19: 45658 | B19: Nicole Pazzini | C19: Associada | D19: {=SUMPRODUCT( (MONTH('Lucros Disponíveis'!$A$2:$A$1000)=MONTH(A19)) * (YEAR('Lucros Disponíveis'!$A$2:$A$1000)=YEAR(A19)) * ('Lucros Disponíveis'!$G$2:$G$1000) )} -> 0 | E19: =IF(D19="", "", D19*11%) -> 0 | F19: =IF(D19="", "", D19*20%) -> 0 | G19: =IF(D19-528 <= 2259.2, 0, IF(D19-528 <= 2826.65, (D19-528)*0.075 - 169.44, IF(D19-528 <= 3751.05, (D19-528)*0.15 - 381.44, IF(D19-528 <= 4664.68, (D19-528)*0.225 - 662.77, (D19-528)*0.275 - 896 ) ) ) ) -> 0 | H19: =IF(D19="", "", D19 -E19-G19) -> 0
A20: 45689 | B20: Nicole Pazzini | C20: Associada | D20: {=SUMPRODUCT( (MONTH('Lucros Disponíveis'!$A$2:$A$1000)=MONTH(A20)) * (YEAR('Lucros Disponíveis'!$A$2:$A$1000)=YEAR(A20)) * ('Lucros Disponíveis'!$G$2:$G$1000) )} -> 0 | E20: =IF(D20="", "", D20*11%) -> 0 | F20: =IF(D20="", "", D20*20%) -> 0 | G20: =IF(D20-528 <= 2259.2, 0, IF(D20-528 <= 2826.65, (D20-528)*0.075 - 169.44, IF(D20-528 <= 3751.05, (D20-528)*0.15 - 381.44, IF(D20-528 <= 4664.68, (D20-528)*0.225 - 662.77, (D20-528)*0.275 - 896 ) ) ) ) -> 0 | H20: =IF(D20="", "", D20 -E20-G20) -> 0
A21: 45717 | B21: Nicole Pazzini | C21: Associada | D21: {=SUMPRODUCT( (MONTH('Lucros Disponíveis'!$A$2:$A$1000)=MONTH(A21)) * (YEAR('Lucros Disponíveis'!$A$2:$A$1000)=YEAR(A21)) * ('Lucros Disponíveis'!$G$2:$G$1000) )} -> 0 | E21: =IF(D21="", "", D21*11%) -> 0 | F21: =IF(D21="", "", D21*20%) -> 0 | G21: =IF(D21-528 <= 2259.2, 0, IF(D21-528 <= 2826.65, (D21-528)*0.075 - 169.44, IF(D21-528 <= 3751.05, (D21-528)*0.15 - 381.44, IF(D21-528 <= 4664.68, (D21-528)*0.225 - 662.77, (D21-528)*0.275 - 896 ) ) ) ) -> 0 | H21: =IF(D21="", "", D21 -E21-G21) -> 0
A22: 45748 | B22: Nicole Pazzini | C22: Associada | D22: {=SUMPRODUCT( (MONTH('Lucros Disponíveis'!$A$2:$A$1000)=MONTH(A22)) * (YEAR('Lucros Disponíveis'!$A$2:$A$1000)=YEAR(A22)) * ('Lucros Disponíveis'!$G$2:$G$1000) )} -> 0 | E22: =IF(D22="", "", D22*11%) -> 0 | F22: =IF(D22="", "", D22*20%) -> 0 | G22: =IF(D22-528 <= 2259.2, 0, IF(D22-528 <= 2826.65, (D22-528)*0.075 - 169.44, IF(D22-528 <= 3751.05, (D22-528)*0.15 - 381.44, IF(D22-528 <= 4664.68, (D22-528)*0.225 - 662.77, (D22-528)*0.275 - 896 ) ) ) ) -> 0 | H22: =IF(D22="", "", D22 -E22-G22) -> 0
A23: 45778 | B23: Nicole Pazzini | C23: Associada | D23: {=SUMPRODUCT( (MONTH('Lucros Disponíveis'!$A$2:$A$1000)=MONTH(A23)) * (YEAR('Lucros Disponíveis'!$A$2:$A$1000)=YEAR(A23)) * ('Lucros Disponíveis'!$G$2:$G$1000) )} -> 0 | E23: =IF(D23="", "", D23*11%) -> 0 | F23: =IF(D23="", "", D23*20%) -> 0 | G23: =IF(D23-528 <= 2259.2, 0, IF(D23-528 <= 2826.65, (D23-528)*0.075 - 169.44, IF(D23-528 <= 3751.05, (D23-528)*0.15 - 381.44, IF(D23-528 <= 4664.68, (D23-528)*0.225 - 662.77, (D23-528)*0.275 - 896 ) ) ) ) -> 0 | H23: =IF(D23="", "", D23 -E23-G23) -> 0
A24: 45809 | B24: Nicole Pazzini | C24: Associada | D24: {=SUMPRODUCT( (MONTH('Lucros Disponíveis'!$A$2:$A$1000)=MONTH(A24)) * (YEAR('Lucros Disponíveis'!$A$2:$A$1000)=YEAR(A24)) * ('Lucros Disponíveis'!$G$2:$G$1000) )} -> 0 | E24: =IF(D24="", "", D24*11%) -> 0 | F24: =IF(D24="", "", D24*20%) -> 0 | G24: =IF(D24-528 <= 2259.2, 0, IF(D24-528 <= 2826.65, (D24-528)*0.075 - 169.44, IF(D24-528 <= 3751.05, (D24-528)*0.15 - 381.44, IF(D24-528 <= 4664.68, (D24-528)*0.225 - 662.77, (D24-528)*0.275 - 896 ) ) ) ) -> 0 | H24: =IF(D24="", "", D24 -E24-G24) -> 0
A25: 45839 | B25: Nicole Pazzini | C25: Associada | D25: {=SUMPRODUCT( (MONTH('Lucros Disponíveis'!$A$2:$A$1000)=MONTH(A25)) * (YEAR('Lucros Disponíveis'!$A$2:$A$1000)=YEAR(A25)) * ('Lucros Disponíveis'!$G$2:$G$1000) )} -> 0 | E25: =IF(D25="", "", D25*11%) -> 0 | F25: =IF(D25="", "", D25*20%) -> 0 | G25: =IF(D25-528 <= 2259.2, 0, IF(D25-528 <= 2826.65, (D25-528)*0.075 - 169.44, IF(D25-528 <= 3751.05, (D25-528)*0.15 - 381.44, IF(D25-528 <= 4664.68, (D25-528)*0.225 - 662.77, (D25-528)*0.275 - 896 ) ) ) ) -> 0 | H25: =IF(D25="", "", D25 -E25-G25) -> 0
A26: 45870 | B26: Nicole Pazzini | C26: Associada | D26: {=SUMPRODUCT( (MONTH('Lucros Disponíveis'!$A$2:$A$1000)=MONTH(A26)) * (YEAR('Lucros Disponíveis'!$A$2:$A$1000)=YEAR(A26)) * ('Lucros Disponíveis'!$G$2:$G$1000) )} -> 0 | E26: =IF(D26="", "", D26*11%) -> 0 | F26: =IF(D26="", "", D26*20%) -> 0 | G26: =IF(D26-528 <= 2259.2, 0, IF(D26-528 <= 2826.65, (D26-528)*0.075 - 169.44, IF(D26-528 <= 3751.05, (D26-528)*0.15 - 381.44, IF(D26-528 <= 4664.68, (D26-528)*0.225 - 662.77, (D26-528)*0.275 - 896 ) ) ) ) -> 0 | H26: =IF(D26="", "", D26 -E26-G26) -> 0
A27: 45901 | B27: Nicole Pazzini | C27: Associada | D27: {=SUMPRODUCT( (MONTH('Lucros Disponíveis'!$A$2:$A$1000)=MONTH(A27)) * (YEAR('Lucros Disponíveis'!$A$2:$A$1000)=YEAR(A27)) * ('Lucros Disponíveis'!$G$2:$G$1000) )} -> 0 | E27: =IF(D27="", "", D27*11%) -> 0 | F27: =IF(D27="", "", D27*20%) -> 0 | G27: =IF(D27-528 <= 2259.2, 0, IF(D27-528 <= 2826.65, (D27-528)*0.075 - 169.44, IF(D27-528 <= 3751.05, (D27-528)*0.15 - 381.44, IF(D27-528 <= 4664.68, (D27-528)*0.225 - 662.77, (D27-528)*0.275 - 896 ) ) ) ) -> 0 | H27: =IF(D27="", "", D27 -E27-G27) -> 0
A28: 45931 | B28: Nicole Pazzini | C28: Associada | D28: {=SUMPRODUCT( (MONTH('Lucros Disponíveis'!$A$2:$A$1000)=MONTH(A28)) * (YEAR('Lucros Disponíveis'!$A$2:$A$1000)=YEAR(A28)) * ('Lucros Disponíveis'!$G$2:$G$1000) )} -> 0 | E28: =IF(D28="", "", D28*11%) -> 0 | F28: =IF(D28="", "", D28*20%) -> 0 | G28: =IF(D28-528 <= 2259.2, 0, IF(D28-528 <= 2826.65, (D28-528)*0.075 - 169.44, IF(D28-528 <= 3751.05, (D28-528)*0.15 - 381.44, IF(D28-528 <= 4664.68, (D28-528)*0.225 - 662.77, (D28-528)*0.275 - 896 ) ) ) ) -> 0 | H28: =IF(D28="", "", D28 -E28-G28) -> 0
A29: 45962 | B29: Nicole Pazzini | C29: Associada | D29: {=SUMPRODUCT( (MONTH('Lucros Disponíveis'!$A$2:$A$1000)=MONTH(A29)) * (YEAR('Lucros Disponíveis'!$A$2:$A$1000)=YEAR(A29)) * ('Lucros Disponíveis'!$G$2:$G$1000) )} -> 0 | E29: =IF(D29="", "", D29*11%) -> 0 | F29: =IF(D29="", "", D29*20%) -> 0 | G29: =IF(D29-528 <= 2259.2, 0, IF(D29-528 <= 2826.65, (D29-528)*0.075 - 169.44, IF(D29-528 <= 3751.05, (D29-528)*0.15 - 381.44, IF(D29-528 <= 4664.68, (D29-528)*0.225 - 662.77, (D29-528)*0.275 - 896 ) ) ) ) -> 0 | H29: =IF(D29="", "", D29 -E29-G29) -> 0
A30: 45992 | B30: Nicole Pazzini | C30: Associada | D30: {=SUMPRODUCT( (MONTH('Lucros Disponíveis'!$A$2:$A$1000)=MONTH(A30)) * (YEAR('Lucros Disponíveis'!$A$2:$A$1000)=YEAR(A30)) * ('Lucros Disponíveis'!$G$2:$G$1000) )} -> 0 | E30: =IF(D30="", "", D30*11%) -> 0 | F30: =IF(D30="", "", D30*20%) -> 0 | G30: =IF(D30-528 <= 2259.2, 0, IF(D30-528 <= 2826.65, (D30-528)*0.075 - 169.44, IF(D30-528 <= 3751.05, (D30-528)*0.15 - 381.44, IF(D30-528 <= 4664.68, (D30-528)*0.225 - 662.77, (D30-528)*0.275 - 896 ) ) ) ) -> 0 | H30: =IF(D30="", "", D30 -E30-G30) -> 0
A31: Lucro do Fundo | B31: Nicole Pazzini | C31: Associada | D31: =(Fundos!G22) -> 0 | E31: =IF(D31="", "", D31*11%) -> 0 | F31: =IF(D31="", "", D31*20%) -> 0 | G31: =IF(D31-528 <= 2259.2, 0, IF(D31-528 <= 2826.65, (D31-528)*0.075 - 169.44, IF(D31-528 <= 3751.05, (D31-528)*0.15 - 381.44, IF(D31-528 <= 4664.68, (D31-528)*0.225 - 662.77, (D31-528)*0.275 - 896 ) ) ) ) -> 0 | H31: =IF(D31="", "", D31 -E31-G31) -> 0

Sheet DRE
A1: Mês | B1: Receita Bruta | C1: Acumulado 12 em meses | D1: Alíquota (SN)% | E1: Alíquota Efetiva | F1: Dedução | G1: Imposto | H1: Despesas com Pessoal | I1: Despesas Gerais | J1: Lucro Líquido | K1: Fundo de Reserva
A2: 45658 | B2: {=SUMPRODUCT((MONTH(Entradas!B$2:B$1000)=MONTH(A2))*(YEAR(Entradas!B$2:B$1000)=YEAR(A2))*(Entradas!C$2:C$1000))} -> 0 | C2: =SUM(B2) -> 0 | D2: =IF(C2<=180000, 4.5, IF(C2<=360000, 9, IF(C2<=720000, 10.2, IF(C2<=1800000, 14, IF(C2<=3600000, 22, IF(C2<=4800000, 33, "Fora do Anexo IV") ) ) ) ) ) -> 4.5 | E2: =IF(C2=0, 0, ((C2*D2/100) - F2) / C2 * 100) -> 0 | F2: =IF(C2<=180000, 0, IF(C2<=360000, 8100, IF(C2<=720000, 12420, IF(C2<=1800000, 39780, IF(C2<=3600000, 183780, IF(C2<=4800000, 828000, 0) ) ) ) ) ) -> 0 | G2: =B2 * E2 / 100 -> 0 | H2: ='Pró-labore'!F3+'Pró-labore'!F19 -> 0 | I2: =Despesas!B3 -> 0 | J2: =B2-G2-H2-I2 -> 0 | K2: =J2*10% -> 0
A3: 45689 | B3: {=SUMPRODUCT((MONTH(Entradas!B$2:B$1000)=MONTH(A3))*(YEAR(Entradas!B$2:B$1000)=YEAR(A3))*(Entradas!C$2:C$1000))} -> 0 | C3: =SUM(B2:B3) -> 0 | D3: =IF(C3<=180000, 4.5, IF(C3<=360000, 9, IF(C3<=720000, 10.2, IF(C3<=1800000, 14, IF(C3<=3600000, 22, IF(C3<=4800000, 33, "Fora do Anexo IV") ) ) ) ) ) -> 4.5 | E3: =IF(C3=0, 0, ((C3*D3/100) - F3) / C3 * 100) -> 0 | F3: =IF(C3<=180000, 0, IF(C3<=360000, 8100, IF(C3<=720000, 12420, IF(C3<=1800000, 39780, IF(C3<=3600000, 183780, IF(C3<=4800000, 828000, 0) ) ) ) ) ) -> 0 | G3: =B3 * E3 / 100 -> 0 | H3: ='Pró-labore'!F4+'Pró-labore'!F20 -> 0 | I3: =Despesas!B4 -> 0 | J3: =B3-G3-H3-I3 -> 0 | K3: =J3*10% -> 0
A4: 45717 | B4: {=SUMPRODUCT((MONTH(Entradas!B$2:B$1000)=MONTH(A4))*(YEAR(Entradas!B$2:B$1000)=YEAR(A4))*(Entradas!C$2:C$1000))} -> 0 | C4: =SUM(B2:B4) -> 0 | D4: =IF(C4<=180000, 4.5, IF(C4<=360000, 9, IF(C4<=720000, 10.2, IF(C4<=1800000, 14, IF(C4<=3600000, 22, IF(C4<=4800000, 33, "Fora do Anexo IV") ) ) ) ) ) -> 4.5 | E4: =IF(C4=0, 0, ((C4*D4/100) - F4) / C4 * 100) -> 0 | F4: =IF(C4<=180000, 0, IF(C4<=360000, 8100, IF(C4<=720000, 12420, IF(C4<=1800000, 39780, IF(C4<=3600000, 183780, IF(C4<=4800000, 828000, 0) ) ) ) ) ) -> 0 | G4: =B4 * E4 / 100 -> 0 | H4: ='Pró-labore'!F5+'Pró-labore'!F21 -> 0 | I4: =Despesas!B5 -> 0 | J4: =B4-G4-H4-I4 -> 0 | K4: =J4*10% -> 0
A5: 45748 | B5: {=SUMPRODUCT((MONTH(Entradas!B$2:B$1000)=MONTH(A5))*(YEAR(Entradas!B$2:B$1000)=YEAR(A5))*(Entradas!C$2:C$1000))} -> 0 | C5: =SUM(B2:B5) -> 0 | D5: =IF(C5<=180000, 4.5, IF(C5<=360000, 9, IF(C5<=720000, 10.2, IF(C5<=1800000, 14, IF(C5<=3600000, 22, IF(C5<=4800000, 33, "Fora do Anexo IV") ) ) ) ) ) -> 4.5 | E5: =IF(C5=0, 0, ((C5*D5/100) - F5) / C5 * 100) -> 0 | F5: =IF(C5<=180000, 0, IF(C5<=360000, 8100, IF(C5<=720000, 12420, IF(C5<=1800000, 39780, IF(C5<=3600000, 183780, IF(C5<=4800000, 828000, 0) ) ) ) ) ) -> 0 | G5: =B5 * E5 / 100 -> 0 | H5: ='Pró-labore'!F6+'Pró-labore'!F22 -> 0 | I5: =Despesas!B6 -> 0 | J5: =B5-G5-H5-I5 -> 0 | K5: =J5*10% -> 0
A6: 45778 | B6: {=SUMPRODUCT((MONTH(Entradas!B$2:B$1000)=MONTH(A6))*(YEAR(Entradas!B$2:B$1000)=YEAR(A6))*(Entradas!C$2:C$1000))} -> 0 | C6: =SUM(B2:B6) -> 0 | D6: =IF(C6<=180000, 4.5, IF(C6<=360000, 9, IF(C6<=720000, 10.2, IF(C6<=1800000, 14, IF(C6<=3600000, 22, IF(C6<=4800000, 33, "Fora do Anexo IV") ) ) ) ) ) -> 4.5 | E6: =IF(C6=0, 0, ((C6*D6/100) - F6) / C6 * 100) -> 0 | F6: =IF(C6<=180000, 0, IF(C6<=360000, 8100, IF(C6<=720000, 12420, IF(C6<=1800000, 39780, IF(C6<=3600000, 183780, IF(C6<=4800000, 828000, 0) ) ) ) ) ) -> 0 | G6: =B6 * E6 / 100 -> 0 | H6: ='Pró-labore'!F7+'Pró-labore'!F23 -> 0 | I6: =Despesas!B7 -> 0 | J6: =B6-G6-H6-I6 -> 0 | K6: =J6*10% -> 0
A7: 45809 | B7: {=SUMPRODUCT((MONTH(Entradas!B$2:B$10000)=MONTH(A7))*(YEAR(Entradas!B$2:B$10000)=YEAR(A7))*(Entradas!C$2:C$10000))} -> 1500 | C7: =SUM(B2:B7) -> 1500 | D7: =IF(C7<=180000, 4.5, IF(C7<=360000, 9, IF(C7<=720000, 10.2, IF(C7<=1800000, 14, IF(C7<=3600000, 22, IF(C7<=4800000, 33, "Fora do Anexo IV") ) ) ) ) ) -> 4.5 | E7: =IF(C7=0, 0, ((C7*D7/100) - F7) / C7 * 100) -> 4.5 | F7: =IF(C7<=180000, 0, IF(C7<=360000, 8100, IF(C7<=720000, 12420, IF(C7<=1800000, 39780, IF(C7<=3600000, 183780, IF(C7<=4800000, 828000, 0) ) ) ) ) ) -> 0 | G7: =B7 * E7 / 100 -> 67.5 | H7: ='Pró-labore'!F8+'Pró-labore'!F24 -> 124.28082 | I7: =Despesas!B8 -> 0 | J7: =B7-G7-H7-I7 -> 1308.2192 | K7: =J7*10% -> 130.82192
A8: 45839 | B8: {=SUMPRODUCT((MONTH(Entradas!B$2:B$1000)=MONTH(A8))*(YEAR(Entradas!B$2:B$1000)=YEAR(A8))*(Entradas!C$2:C$1000))} -> 330 | C8: =SUM(B2:B8) -> 1830 | D8: =IF(C8<=180000, 4.5, IF(C8<=360000, 9, IF(C8<=720000, 10.2, IF(C8<=1800000, 14, IF(C8<=3600000, 22, IF(C8<=4800000, 33, "Fora do Anexo IV") ) ) ) ) ) -> 4.5 | E8: =IF(C8=0, 0, ((C8*D8/100) - F8) / C8 * 100) -> 4.5 | F8: =IF(C8<=180000, 0, IF(C8<=360000, 8100, IF(C8<=720000, 12420, IF(C8<=1800000, 39780, IF(C8<=3600000, 183780, IF(C8<=4800000, 828000, 0) ) ) ) ) ) -> 0 | G8: =B8 * E8 / 100 -> 14.85 | H8: ='Pró-labore'!F9+'Pró-labore'!F25 -> 48.073729 | I8: =Despesas!B9 -> 0 | J8: =B8-G8-H8-I8 -> 267.07627 | K8: =J8*10% -> 26.707627
A9: 45870 | B9: {=SUMPRODUCT((MONTH(Entradas!B$2:B$1000)=MONTH(A9))*(YEAR(Entradas!B$2:B$1000)=YEAR(A9))*(Entradas!C$2:C$1000))} -> 330 | C9: =SUM(B2:B9) -> 2160 | D9: =IF(C9<=180000, 4.5, IF(C9<=360000, 9, IF(C9<=720000, 10.2, IF(C9<=1800000, 14, IF(C9<=3600000, 22, IF(C9<=4800000, 33, "Fora do Anexo IV") ) ) ) ) ) -> 4.5 | E9: =IF(C9=0, 0, ((C9*D9/100) - F9) / C9 * 100) -> 4.5 | F9: =IF(C9<=180000, 0, IF(C9<=360000, 8100, IF(C9<=720000, 12420, IF(C9<=1800000, 39780, IF(C9<=3600000, 183780, IF(C9<=4800000, 828000, 0) ) ) ) ) ) -> 0 | G9: =B9 * E9 / 100 -> 14.85 | H9: ='Pró-labore'!F10+'Pró-labore'!F26 -> 48.073729 | I9: =Despesas!B10 -> 0 | J9: =B9-G9-H9-I9 -> 267.07627 | K9: =J9*10% -> 26.707627
A10: 45901 | B10: {=SUMPRODUCT((MONTH(Entradas!B$2:B$1000)=MONTH(A10))*(YEAR(Entradas!B$2:B$1000)=YEAR(A10))*(Entradas!C$2:C$1000))} -> 0 | C10: =SUM(B2:B10) -> 2160 | D10: =IF(C10<=180000, 4.5, IF(C10<=360000, 9, IF(C10<=720000, 10.2, IF(C10<=1800000, 14, IF(C10<=3600000, 22, IF(C10<=4800000, 33, "Fora do Anexo IV") ) ) ) ) ) -> 4.5 | E10: =IF(C10=0, 0, ((C10*D10/100) - F10) / C10 * 100) -> 4.5 | F10: =IF(C10<=180000, 0, IF(C10<=360000, 8100, IF(C10<=720000, 12420, IF(C10<=1800000, 39780, IF(C10<=3600000, 183780, IF(C10<=4800000, 828000, 0) ) ) ) ) ) -> 0 | G10: =B10 * E10 / 100 -> 0 | H10: ='Pró-labore'!F11+'Pró-labore'!F27 -> 0 | I10: =Despesas!B11 -> 0 | J10: =B10-G10-H10-I10 -> 0 | K10: =J10*10% -> 0
A11: 45931 | B11: {=SUMPRODUCT((MONTH(Entradas!B$2:B$1000)=MONTH(A11))*(YEAR(Entradas!B$2:B$1000)=YEAR(A11))*(Entradas!C$2:C$1000))} -> 0 | C11: =SUM(B2:B11) -> 2160 | D11: =IF(C11<=180000, 4.5, IF(C11<=360000, 9, IF(C11<=720000, 10.2, IF(C11<=1800000, 14, IF(C11<=3600000, 22, IF(C11<=4800000, 33, "Fora do Anexo IV") ) ) ) ) ) -> 4.5 | E11: =IF(C11=0, 0, ((C11*D11/100) - F11) / C11 * 100) -> 4.5 | F11: =IF(C11<=180000, 0, IF(C11<=360000, 8100, IF(C11<=720000, 12420, IF(C11<=1800000, 39780, IF(C11<=3600000, 183780, IF(C11<=4800000, 828000, 0) ) ) ) ) ) -> 0 | G11: =B11 * E11 / 100 -> 0 | H11: ='Pró-labore'!F12+'Pró-labore'!F28 -> 0 | I11: =Despesas!B12 -> 0 | J11: =B11-G11-H11-I11 -> 0 | K11: =J11*10% -> 0
